Workbook

Sheet Summary
A1: Intune Baseline — Policy to Security Framework Mapping
A2: Source: CIS_Compliance_Baseline_v2.xlsx (‘Compliance Baseline’ sheet), cross-referenced against the 222 policy files in source-pack/
A3: Every NIST / ISO value is copied verbatim from the workbook. Nothing is inferred: where the workbook has no data, the cells are left blank and the policy is marked UNMAPPED.
A5: COVERAGE
A6: Policies in the pack | B6: =COUNTA('Policy Mapping'!A2:A223) -> 222 | C6: One row per policy file.
A7: Mapped to a framework | B7: =COUNTIF('Policy Mapping'!N2:N223,"mapped") -> 198 | C7: Has a workbook row with NIST / ISO values.
A8: Unmapped | B8: =COUNTIF('Policy Mapping'!N2:N223,"<>mapped") -> 24 | C8: Workbook row is numbered but blank.
A9: Coverage % | B9: =IF(B6=0,0,B7/B6) -> 0.89189189 | C9: Mapped as a share of all policies.
A10: Distinct NIST controls | B10: =SUMPRODUCT(('Control Coverage'!A2:A48="NIST SP 800-53 Rev 5")*1) -> 31 | C10: Rev 5 controls cited at least once.
A11: Distinct ISO clauses | B11: =SUMPRODUCT(('Control Coverage'!A2:A48="ISO/IEC 27001:2022")*1) -> 16 | C11: 27001:2022 Annex A clauses cited.
A13: HOW EACH MAPPING WAS MATCHED
A14: Every mapping is traceable. ‘match_method’ on the Policy Mapping tab records how the workbook row was tied to the policy file, so any row can be spot-checked.
A15: Match method | B15: Policies | C15: What it means
A16: exact | B16: =COUNTIF('Policy Mapping'!O2:O223,"exact") -> 164 | C16: Workbook policy name equals the filename, character for character.
A17: punctuation | B17: =COUNTIF('Policy Mapping'!O2:O223,"punctuation") -> 14 | C17: Matched after normalising punctuation, .mobileconfig, export timestamps, or a mangled curly apostrophe (#U2019).
A18: whitespace | B18: =COUNTIF('Policy Mapping'!O2:O223,"whitespace") -> 10 | C18: Matched after collapsing double spaces and trimming.
A19: prefix | B19: =COUNTIF('Policy Mapping'!O2:O223,"prefix") -> 10 | C19: Matched after normalising a differing rule-name prefix, e.g. workbook “ASR - BLOCK - Block X” vs file “CISv4 - WIN - L1 - ASR: Block X”.
A20: unmapped | B20: =COUNTIF('Policy Mapping'!O2:O223,"unmapped") -> 24 | C20: No workbook row exists for this policy — the row is numbered but entirely blank.
A23: KNOWN ISSUES IN THE SOURCE WORKBOOK
A24: • 24 rows are numbered but completely blank — the workbook presents itself as 222 policies but documents 198. These cannot be mapped from anything in the pack; the workbook has to be filled in. See the ‘Unmapped Gap’ tab.
A25: • 15 rows record a literal “-” instead of a control. All are Edge CIS items, mostly browser-UX controls with no clean framework analogue. They appear as “(none recorded)” on the Policy x Control tab.
A26: • One level disagreement: “Configure the list of types that are excluded from synchronization” is L2 in the workbook but L1 in the filename. This workbook reports the workbook’s value (L2).
A27: • 34 policies were only matched after normalising naming drift between the workbook and the exported filenames (double spaces, prefixes, punctuation). Their mappings are the workbook’s own — see match_method.

Sheet Operational Impact
A1: Operational impact — effect on operations and end-user experience
A2: Scoped to a typical client profile: CAD engineers, a small dev team, majority general office staff, 200+ endpoints. Every row states what this pack ACTUALLY configures, what the user experiences, and how the service desk should handle it. The Service Desk Brief tab is the same information filtered to the handover sheet — both tabs are generated from one source, so they cannot drift apart.
A4: Policy | B4: Configured as | C4: Who it hits | D4: Assessed severity | E4: What actually breaks | F4: What the user reports | G4: Service desk handling | H4: What the service desk should do | I4: When it bites | J4: Mitigation | K4: Evidence / provenance
A5: CISv3 - EDGE - L2 - Allow file selection dialogs | B5: AllowFileSelectionDialogs = 0 (blocked) | C5: All users · Office | D5: HIGH | E5: File selection dialogs are blocked in Edge. Users cannot browse to pick a file — no attaching to webmail, no uploading a drawing to a client portal, no 'Upload' in SharePoint/Teams web, no attaching to a support ticket. Save-as dialogs are affected too. | F5: “I can't attach a file / the Upload button does nothing” | G5: Expected | H5: Not a fault and there is no client-side fix. Escalate — this is an L2 scoping decision. | I5: First time anyone tries to upload or attach anything in the browser. Immediate and constant. | J5: This is an L2 control. For an office-heavy fleet, scope the Edge L2 set out entirely or exclude this single policy. Test the customer's actual web apps — portals, ticketing, cloud CAD — first. | K5: Setting verified + Microsoft Edge policy docs
A6: CISv3 - EDGE - L2 - Allow or block audio capture | B6: AudioCaptureAllowed = 0 (microphone blocked) | C6: All users | D6: HIGH | E6: Websites cannot access the microphone. Browser-based Teams, Zoom, Google Meet and Webex calls have no audio. Web dictation and voice tools stop working. | F6: “I have no microphone in the Teams/Zoom web app” | G6: Expected | H6: Move the user to the desktop client. Escalate if browser calls are a business requirement. | I6: First browser-based call after apply. | J6: Survivable if the customer uses desktop clients exclusively; not if anyone joins calls in a browser (guests, contractors, BYOD). Confirm before deploying. L2 — scope out with the rest if unsure. | K6: Setting verified + Microsoft Edge policy docs
A7: CISv3 - EDGE - L2 - Allow or deny screen capture | B7: ScreenCaptureAllowed = 0 (blocked) | C7: All users · Service desk | D7: HIGH | E7: Sites cannot capture the screen. Screen sharing in browser-based Teams/Zoom/Meet fails, and browser-delivered remote support tools cannot show or take the screen. | F7: “I can't share my screen in a browser meeting” | G7: Expected | H7: Use the desktop client. If your own remote-support tool is browser-based, escalate urgently. | I7: First time someone tries to share their screen from a browser. | J7: Check how the service desk actually does remote support — if it is browser-delivered, this breaks their own tooling. L2, scope out if so. | K7: Setting verified + Microsoft Edge policy docs
A8: Network security: LAN Manager auth level + SMBv1 disabled + SMB signing always | B8: LmCompatibilityLevel = 5 (NTLMv2 only, refuse LM & NTLM) · SMBv1 client driver = 4 (disabled) · SMBv1 server = 0 · client and server digital signing = 1 (always) | C8: CAD · Office · Service desk | D8: HIGH | E8: Legacy network kit that cannot do NTLMv2, SMBv2+ or SMB signing stops authenticating. In an engineering or architecture firm that typically means the office MFP's scan-to-folder stops working, older NAS boxes become unreachable, and network plotters or scanners with old firmware drop off. SMB signing also adds CPU cost to large transfers — noticeable opening big CAD assemblies from a file server. | F8: “The photocopier can't scan to my folder any more” | G8: Investigate | H8: Check the device's firmware and SMB/auth capability. A firmware update usually fixes it — do not weaken the policy per-device. | I8: Immediately for authentication; file-open slowdowns show up under load. | J8: Inventory the network kit BEFORE deploying: every MFP, scanner, plotter and NAS. Firmware updates fix most of it. This is the classic 'security baseline broke the photocopier' scenario and it is very likely in this client profile. | K8: Settings verified + Microsoft LAN Manager authentication level docs. MFP/NAS impact is assessment — inventory to confirm.
F9: “Opening drawings from the server got slow” | G9: Investigate | H9: Confirm it correlates with the rollout. Escalate with timings — this is a tuning decision, not a device fault.
A10: Windows Hello for Business — Require Security Device + Exclude TPM 1.2 + Disable Post Logon Provisioning + Multi-Factor Unlock | B10: RequireSecurityDevice = True · ExcludeSecurityDevices/TPM12 = True · DisablePostLogonProvisioning = True · Multi-factor unlock: group A = face/fingerprint, group B = PIN/face/fingerprint, plus a bluetooth proximity signal at rssiMin -10 | C10: CAD (desktop towers) · All users | D10: HIGH | E10: Two compounding problems. (1) A device without TPM 2.0 will not provision Hello, and because post-logon provisioning is disabled the user is never prompted again — they silently stay on passwords and nobody notices the passwordless project didn't land. (2) Multi-factor unlock needs a group A factor, which is face or fingerprint. Desktop CAD workstations typically have neither, so those users may not be able to use Hello at all. The bluetooth signal at rssiMin -10 also needs the phone very close to register. | F10: “Windows Hello never asked me to set up / won't work on my desktop PC” | G10: Investigate | H10: Check TPM version and whether the device has a camera or fingerprint reader. Escalate — a fleet hardware question, not a per-user fix. | I10: At enrolment. Silent — this fails quietly rather than erroring. | J10: Audit TPM version across the fleet first. Decide explicitly whether desktop towers get biometric hardware or are excluded from multi-factor unlock. Loosen rssiMin if bluetooth proximity is used at all. | K10: Settings verified across 5 policies (4 are legacy OMA-URI) + Workbook note #22. Desktop-tower biometric gap is assessment.
A11: Baseline - Configure Windows protected print | B11: Protected Print Mode = Enabled (1) | C11: CAD · Office · Service desk | D11: HIGH | E11: Disables ALL third-party v3/v4 print drivers. Only Mopria-certified IPP printers work. Large-format plotters (DesignJet, imagePROGRAF, Océ) and MFP finishing — stapling, booklet, secure/PIN release — stop working. Legacy port monitors and DLL-based print utilities stop working. | F11: “I can't add the plotter / my printer driver won't install” | G11: Expected | H11: Check the printer against the Mopria certified list. If not certified it needs a policy exclusion — escalate, do not rebuild the machine. | I11: First print job after apply. Immediate and fleet-wide. | J11: Inventory printers against the Mopria certified list BEFORE deploying. If any plotter or MFP is not certified, exclude this policy or scope it to office devices only. Reversible — you can revert to driver-based printing. | K11: Setting verified + Microsoft 'Windows protected print mode for enterprises' docs
F12: “Stapling / booklet / secure PIN release has disappeared from the print dialog” | G12: Expected | H12: Escalate as a scoping decision. There is no client-side fix.
A13: CISv4 - WIN - L1 - UAC: Behavior of the elevation prompt for standard users | B13: ConsentPromptBehaviorUser = 0 (automatically deny) | C13: All users · Service desk | D13: HIGH | E13: Standard users get NO elevation prompt — the operation returns 'Access denied' and fails. A user cannot be talked through entering admin credentials because no prompt appears. Any install, driver update or self-elevating app just fails. | F13: “Nothing happens when I try to install something — it just says access denied” | G13: Expected | H13: Do not try to talk the user through a prompt — there isn't one. Use LAPS / admin-by-request / RMM elevation. | I13: Any time a non-admin hits something needing elevation. Constant. | J13: Ensure the service desk has a working elevation path first — LAPS, admin-by-request, or RMM elevation. Brief them that 'access denied with no prompt' is expected, not a broken machine. | K13: Setting verified + Microsoft UAC policy docs
A14: CISv4 - WIN - L1 - Credential Guard | B14: LsaCfgFlags = 1 (Enabled WITH UEFI lock) | C14: Dev team · Service desk | D14: HIGH | E14: Credential Guard with UEFI lock CANNOT be turned off remotely. If it breaks a developer's VM (VMware without nested virtualisation) or fails on incompatible hardware, the fix needs physical firmware access — a site visit per affected device across 200 endpoints. | F14: “My VM won't start / VMware says it can't run” | G14: Escalate immediately | H14: Escalate — needs a physical firmware change. Flag early: every affected machine is a site visit. | I14: At next reboot. Hardware/VM incompatibility shows immediately. | J14: Use LsaCfgFlags = 2 (enabled WITHOUT lock) for pilot so it stays remotely reversible; move to 1 only once proven. Verify TPM 2.0 + UEFI + 64-bit, and test dev machines running VMware/Hyper-V specifically. | K14: Setting verified + Microsoft DeviceGuard CSP docs. NOTE: the source workbook does NOT flag this — its note #8 covers LSA protection's UEFI lock only.
A15: Baseline - Device Control | B15: RemovableDiskDenyWriteAccess = 1 · AllowDirectMemoryAccess = 0 · AllowBluetooth = 2 | C15: CAD · Office · Service desk | D15: HIGH | E15: Writing to USB storage is denied — blocks 'copy the drawing set to a stick for site or the client'. DMA blocking can affect Thunderbolt docks and eGPU enclosures used on CAD workstations. | F15: “I can't save to my USB stick” | G15: Expected | H15: Point the user to the agreed alternative (OneDrive/SharePoint). Do not disable per-device. | I15: First attempt to save to USB. Very visible. | J15: Agree the file-transfer alternative with the customer BEFORE deploying. Pilot on a real CAD workstation with its actual dock. | K15: Settings verified + Workbook note #17. Dock/eGPU impact is assessment — test on real hardware.
F16: “My dock / second monitor stopped working” | G16: Investigate | H16: Confirm whether the dock is Thunderbolt/DMA-based. Test on an unenrolled machine before assuming hardware failure.
A17: Edge + Chrome extension allow-lists | B17: Default-deny allow-list (customer extension IDs required) | C17: All users | D17: HIGH | E17: Deployed unconfigured, ALL browser extensions are blocked — corporate VPN clients, password managers (Keeper), accessibility tools and screen readers included. | F17: “All my browser extensions vanished” | G17: Expected | H17: Collect the extension ID and escalate for the approved list. Do not sideload. | I17: Immediately on apply. | J17: Populate EdgeApprovedExtensionIds / ChromeApprovedExtensionIds before deploying. Survey what users actually have — 200 users will have a long tail nobody documented. | K17: Workbook notes #14 and #21 (both HIGH)
A18: CISv3 - EDGE - L2 - Allow users to proceed from the HTTPS warning page | B18: SSLErrorOverrideAllowed = 0 | C18: CAD · Service desk | D18: MEDIUM | E18: Users cannot click through a certificate warning. Internal kit with self-signed or expired certs becomes unreachable in Edge: NAS admin pages, printer and plotter web UIs, CAD licence server consoles, older intranet appliances. | F18: “I can't open the NAS / printer / licence server web page — the cert error won't let me through” | G18: Expected | H18: Install a proper certificate on the device, or escalate for an exclusion. Do not tell users to switch browser. | I18: First time someone opens an internal device's web page. | J18: Inventory internal HTTPS endpoints with self-signed certs and either install proper certs or exclude this policy. The service desk hits this constantly. | K18: Setting verified + Microsoft Edge policy docs. Internal-kit impact is assessment.
A19: Baseline - Microsoft Defender Antivirus (cloud block level + local admin merge + network file scanning) | B19: CloudBlockLevel = 6 (High Plus) · DisableLocalAdminMerge = 1 · AllowScanningNetworkFiles = 1 · PUAProtection = 1 · AvgCPULoadFactor = 30 | C19: CAD · Dev team | D19: MEDIUM | E19: High Plus cloud blocking is aggressive and flags rare or unsigned software — exactly what niche CAD plugins, licence managers and in-house dev tools look like. Local admins cannot add their own Defender exclusions, so every false positive becomes a ticket. Real-time scanning of network files adds latency opening large CAD assemblies from a file server. | F19: “Defender quarantined our CAD plugin / licence manager” | G19: Investigate | H19: Do not ask the user to add an exclusion — they can't. Collect the file path and hash and escalate for a central exclusion. | I19: False positives cluster in the first 2-4 weeks; file-open latency is immediate under load. | J19: Pre-stage exclusions for the CAD suite and licence manager before deploying. Monitor Defender alerts closely in the pilot. Have a fast central path to add exclusions, since users and local admins can no longer self-serve. | K19: Settings verified + Workbook notes #9 and #10. CAD plugin false-positive risk is assessment.
A20: CISv4 - WIN - L1 - Configure Lsa Protected Process (Enabled with UEFI Lock) | B20: ConfigureLsaProtectedProcess = 1 (UEFI lock) | C20: Service desk | D20: MEDIUM | E20: Same reversal problem as Credential Guard — undoing it needs BIOS-level intervention. Also blocks tools that inject into LSASS (some SSO agents, older RMM credential helpers). | F20: “Our SSO agent / credential helper stopped working after a reboot” | G20: Investigate | H20: Check whether the tool injects into LSASS. Escalate — reversing this needs BIOS access. | I20: At reboot; tool incompatibility surfaces within days. | J20: Deploy without UEFI lock first, confirm no tooling breaks, then lock. Agree BIOS access methodology before broad deployment. | K20: Setting verified + Workbook note #8
A21: CISv4 - WIN - L1 - ASR: Block untrusted and unsigned processes that run from USB | B21: Set to BLOCK — the only ASR rule shipping in block mode | C21: CAD · Service desk | D21: MEDIUM | E21: Unsigned executables run from removable media are blocked. Hits CAD licence dongles that ship an unsigned helper, vendor utilities run from USB, and portable diagnostic tools the service desk carries on a stick. | F21: “My CAD licence dongle stopped working” | G21: Investigate | H21: Check Defender logs for an ASR block event. If confirmed it needs an ASR exclusion — escalate. | I21: First time someone runs a tool from USB. | J21: Confirm whether any CAD licensing uses a USB dongle with an unsigned component. Keep service desk tooling on a network share or signed media. | K21: Setting verified. CAD dongle impact is assessment — verify against this customer's licensing.
A22: CISv4 - WIN - L1 - Allow Basic authentication (WinRM Client) | B22: Client = 0 (Basic auth disabled) | C22: Service desk | D22: MEDIUM | E22: Remote management tools using WinRM with username/password basic auth stop working. Kerberos and certificate auth still work. | F22: “Our remote support tool can't connect to this machine” | G22: Expected | H22: Confirm the tool's auth method. Migrating to Kerberos is the fix, not a per-device exception. | I22: Next time the RMM or a script connects. | J22: Identify RMM/automation using WinRM basic auth and migrate to Kerberos before deploying. Most likely policy to break the service desk's own tooling. | K22: Setting verified + Workbook note #12
A23: Edge: password manager disabled + sync disabled + import disabled | B23: PasswordManagerEnabled = 0 · SyncDisabled = 1 · ImportSavedPasswords / autofill / browser settings all = 0 | C23: Office · Service desk | D23: MEDIUM | E23: Edge will not save or autofill passwords, will not sync favourites and settings between a user's devices, and cannot import from another browser. For users with no corporate password manager this is a large day-one behaviour change and a password-reset ticket spike. | F23: “Edge won't save my passwords and my favourites didn't follow me” | G23: Expected | H23: Direct the user to the corporate password manager. Favourites must be exported manually before a rebuild. | I23: Immediately, and heavily during onboarding or machine refresh. | J23: Deploy a password manager (Keeper is already in this customer's approved extension list) and communicate it BEFORE these land. Sequence after any browser migration. | K23: Settings verified. Ticket-spike expectation is assessment.
F24: “I can't import my passwords into Edge” | G24: Expected | H24: Direct the user to the corporate password manager.
A25: Edge: IE mode reload blocked · ClickOnce blocked · DirectInvoke blocked | B25: InternetExplorerIntegrationReloadInIEModeAllowed = 0 · ClickOnceEnabled = 0 · DirectInvokeEnabled = 0 | C25: CAD · Office | D25: MEDIUM | E25: Legacy line-of-business web apps break. ClickOnce is still how a number of engineering and ERP vendors deploy their client; DirectInvoke is how some document systems open files directly. Users also cannot reload an unlisted site in IE mode. | F25: “Our ERP / document system won't launch from the browser” | G25: Investigate | H25: Identify how the app launches and escalate to add the site to the IE mode list or exclude the policy. | I25: When someone opens the affected app. | J25: Ask the customer what legacy web apps exist — engineering firms commonly have one ERP or document management system that needs one of these. Add sites to the IE mode list rather than leaving users to self-serve. | K25: Settings verified. Legacy app impact is assessment — confirm the app inventory.
A26: Baseline - Bitlocker Policy (BitLocker To Go) | B26: Unencrypted USB drives become read-only | C26: All users | D26: MEDIUM | E26: Users are prompted to encrypt a USB drive before writing. Intended, but reads as 'my USB stick is broken'. Compounds with Device Control above, which denies USB writes outright. | F26: “My USB stick has gone read-only” | G26: Expected | H26: Expected — the drive needs BitLocker encryption before it can be written to. | I26: First write to an unencrypted stick. | J26: Brief end users and the service desk before deploying. | K26: Workbook note #3 (INFO — intended behaviour)
A27: Baseline - Windows AI - Turn Off Copilot in Windows (User) | B27: TurnOffWindowsCopilot = 1 (user scope) · Click To Do disabled · Edge GenAI local model off · Recall blocked | C27: Office | D27: MEDIUM | E27: Copilot in Windows is removed for users. If the customer is paying for M365 Copilot or has staff already using it, this is a visible and unpopular removal that will be read as a fault. | F27: “Copilot has disappeared” | G27: Expected | H27: If the customer pays for M365 Copilot, escalate — likely a scoping error rather than an intended control. | I27: Immediately. | J27: Confirm the customer's AI position and licensing BEFORE deploying category 10. This is a business decision, not a security default — if they've bought Copilot, exclude this policy. | K27: Settings verified. Licensing conflict is assessment — ask the customer.
A28: Baseline - Windows Security Experience | B28: disablevirusui = 1 · disablenetworkui = 1 · disabledevicesecurityui = 1 · disableaccountprotectionui = 1 · disableappbrowserui = 1 · disablehealthui = 1 · disablefamilyui = 1 · hideransomwaredatarecovery = 1 · hidewindowssecuritynotificationareacontrol = 1 · disableenhancednotifications = 1 | C28: All users · Service desk | D28: MEDIUM | E28: Nearly every page of the Windows Security app is hidden — virus and threat protection, firewall and network protection, device security, account protection, app and browser control, and device health. The system tray icon is hidden too. Users cannot see whether protection is on, run a manual scan, view a detection, or release a file from quarantine. Critically, the service desk loses a standard triage step: they can no longer ask a user to open Windows Security and read out what it says. | F28: “Windows Security is empty / I can't tell if my antivirus is working” | G28: Expected | H28: Expected — the UI is hidden by policy, protection is still running. Confirm state from the Defender portal, not the endpoint. | I28: Immediately. Noticed the first time anyone tries to check their own protection status or the desk tries to triage a Defender issue. | J28: Make sure the desk triages Defender from the Defender portal or via the RMM instead of the local UI, and knows the local UI is intentionally empty. If the customer's users are expected to self-serve any Defender interaction at all, this needs scoping out. | K28: Settings verified. Service desk triage impact is assessment.
F29: “I can't run a virus scan / release a file from quarantine” | G29: Expected | H29: The user cannot do this themselves. Action it centrally from the Defender portal.
A30: ASR - Enable Controlled Folder Access (AUDIT mode) | B30: EnableControlledFolderAccess = 2 (audit) | C30: CAD · Office · Service desk | D30: LOW | E30: Blocks nothing — but still raises user-visible Defender notifications when an app writes to a protected folder. Users report these as 'a virus warning', so the policy costs ticket volume while providing logging only. CAD autosave and backup agents are the usual triggers. | F30: “Defender is warning about a file in my Documents folder” | G30: Expected — not blocking | H30: Reassure the user nothing was blocked. Log it — these events are the evidence for deciding whether block mode is safe. | I30: Continuously, wherever apps write to Documents or Desktop. | J30: Brief the desk that these are audit events, not blocks. Treat the volume as free intelligence — it is exactly the evidence needed to decide whether block mode would ever be safe here. | K30: Setting verified + Workbook note #5. Ticket-volume effect is assessment.
A31: CISv4 - WIN - L1 - Interactive logon: Machine inactivity limit | B31: MachineInactivityLimit = 900 seconds (15 minutes) | C31: CAD · Office | D31: LOW | E31: Screen locks after 15 minutes idle. CAD engineers watching a long render, plot or simulation will lock repeatedly while monitoring a job that needs no input. | F31: “My screen keeps locking while I'm watching a render” | G31: Expected | H31: Expected. Escalate only if there is a business case for a longer limit on CAD workstations. | I31: Constant, low-grade. | J31: Usually acceptable and hard to argue against with an auditor. Mention it in user comms so it isn't reported as a fault. | K31: Setting verified. CAD render impact is assessment.
A32: CISv4 - WIN - L2 - RDS idle session time limit | B32: IdleLimit = 900000 ms (15 minutes) | C32: Office · Service desk | D32: LOW | E32: Idle remote sessions disconnect after 15 minutes — awkward where staff RDP into a shared workstation or licence-server box and leave a long job running. | F32: “My remote session keeps dropping” | G32: Expected | H32: If someone relies on long unattended sessions, escalate as a scoping decision. | I32: Any idle remote session. | J32: Confirm nobody relies on long-running unattended remote sessions (CAD rendering, batch plotting on a shared box). | K32: Setting verified. Rendering/batch impact is assessment.
A33: Edge minor UX set: InPrivate off · Google Cast off · background apps off · profile creation off | B33: InPrivateModeAvailability = 1 (disabled) · EnableMediaRouter = 0 · BackgroundModeEnabled = 0 · BrowserAddProfileEnabled = 0 | C33: Office · Dev team | D33: LOW | E33: No InPrivate windows (devs use these to test as an anonymous user), no Google Cast to meeting-room screens, no second browser profile for a personal or client-tenant login. | F33: “I can't open an InPrivate window / cast to the meeting room screen” | G33: Expected | H33: Expected. Escalate only if meeting rooms depend on Cast. | I33: Ad hoc. | J33: Generally acceptable. Check whether meeting rooms rely on Cast, and whether anyone legitimately needs a second Edge profile for a client tenant. | K33: Settings verified. Use-case impact is assessment.
A35: VERIFIED SAFE — will not cause problems, despite what the source workbook's warnings imply
A36: Worth knowing so you don't over-scope the pilot or talk a customer out of controls they can safely have. Several policies the workbook rates HIGH risk ship in AUDIT mode in this pack, so they log without blocking.
A37: Policy | B37: Configured as | C37: Why it is safe as shipped | D37: Evidence
A38: ASR - Block process creations from PSExec and WMI | B38: Set to AUDIT | C38: Will NOT break RMM tooling or service desk scripts, despite the workbook rating it MEDIUM risk. | D38: Setting verified · workbook note #6
A39: ASR - Block execution of potentially obfuscated scripts | B39: Set to AUDIT | C39: Will NOT block developer build scripts, minified or packed JavaScript, or installer scripts. | D39: Setting verified
A40: ASR - Block all Office applications from creating child processes | B40: Set to AUDIT | C40: Will NOT break Office macros, add-ins or Office automation, despite the workbook rating it HIGH. | D40: Setting verified · workbook note #4
A41: Baseline - Windows Subsystem For Linux | B41: AllowWSL = 1 (permitted) | C41: WSL2 remains available to the dev team. Only WSL1 is blocked (AllowWSL1 = 0), which is rarely used. Kernel, networking, nested virtualisation and debug shell all remain user-configurable. | D41: Setting verified
A42: CISv3 - EDGE - L1 - Clear browsing data when Edge closes | B42: ClearBrowsingDataOnExit = 0 (disabled) | C42: Users will NOT be signed out of web apps every time Edge closes. The workbook's note #19 warns about this behaviour, but the policy as shipped does not enable it. | D42: Setting verified · contradicts workbook note #19
...

Sheet Service Desk Brief
A1: Service desk brief — expected calls after this baseline lands
A2: Hand this to the service desk before the pilot. Every row also appears on the Operational Impact tab against the policy that causes it — same source, so the two cannot disagree. Prevents the classic failure: a correctly-hardened endpoint gets rebuilt because nobody knew the control was intentional.
A4: User reports | B4: Caused by | C4: Expected or fault? | D4: Severity | E4: Why it happens | F4: What the service desk should do
A5: “I can't attach a file / the Upload button does nothing” | B5: CISv3 - EDGE - L2 - Allow file selection dialogs | C5: Expected | D5: HIGH | E5: File selection dialogs are blocked in Edge. Users cannot browse to pick a file — no attaching to webmail, no uploading a drawing to a client portal, no 'Upload' in SharePoint/Teams web, no attaching to a support ticket. Save-as dialogs are affected too. | F5: Not a fault and there is no client-side fix. Escalate — this is an L2 scoping decision.
A6: “I have no microphone in the Teams/Zoom web app” | B6: CISv3 - EDGE - L2 - Allow or block audio capture | C6: Expected | D6: HIGH | E6: Websites cannot access the microphone. Browser-based Teams, Zoom, Google Meet and Webex calls have no audio. Web dictation and voice tools stop working. | F6: Move the user to the desktop client. Escalate if browser calls are a business requirement.
A7: “I can't share my screen in a browser meeting” | B7: CISv3 - EDGE - L2 - Allow or deny screen capture | C7: Expected | D7: HIGH | E7: Sites cannot capture the screen. Screen sharing in browser-based Teams/Zoom/Meet fails, and browser-delivered remote support tools cannot show or take the screen. | F7: Use the desktop client. If your own remote-support tool is browser-based, escalate urgently.
A8: “The photocopier can't scan to my folder any more” | B8: Network security: LAN Manager auth level + SMBv1 disabled + SMB signing always | C8: Investigate | D8: HIGH | E8: Legacy network kit that cannot do NTLMv2, SMBv2+ or SMB signing stops authenticating. In an engineering or architecture firm that typically means the office MFP's scan-to-folder stops working, older NAS boxes become unreachable, and network plotters or scanners with old firmware drop off. SMB signin | F8: Check the device's firmware and SMB/auth capability. A firmware update usually fixes it — do not weaken the policy per-device.
A9: “Opening drawings from the server got slow” | B9: Network security: LAN Manager auth level + SMBv1 disabled + SMB signing always | C9: Investigate | D9: HIGH | E9: Legacy network kit that cannot do NTLMv2, SMBv2+ or SMB signing stops authenticating. In an engineering or architecture firm that typically means the office MFP's scan-to-folder stops working, older NAS boxes become unreachable, and network plotters or scanners with old firmware drop off. SMB signin | F9: Confirm it correlates with the rollout. Escalate with timings — this is a tuning decision, not a device fault.
A10: “Windows Hello never asked me to set up / won't work on my desktop PC” | B10: Windows Hello for Business — Require Security Device + Exclude TPM 1.2 + Disable Post Logon Provisioning + Multi-Factor Unlock | C10: Investigate | D10: HIGH | E10: Two compounding problems. (1) A device without TPM 2.0 will not provision Hello, and because post-logon provisioning is disabled the user is never prompted again — they silently stay on passwords and nobody notices the passwordless project didn't land. (2) Multi-factor unlock needs a group A factor, | F10: Check TPM version and whether the device has a camera or fingerprint reader. Escalate — a fleet hardware question, not a per-user fix.
A11: “I can't add the plotter / my printer driver won't install” | B11: Baseline - Configure Windows protected print | C11: Expected | D11: HIGH | E11: Disables ALL third-party v3/v4 print drivers. Only Mopria-certified IPP printers work. Large-format plotters (DesignJet, imagePROGRAF, Océ) and MFP finishing — stapling, booklet, secure/PIN release — stop working. Legacy port monitors and DLL-based print utilities stop working. | F11: Check the printer against the Mopria certified list. If not certified it needs a policy exclusion — escalate, do not rebuild the machine.
A12: “Stapling / booklet / secure PIN release has disappeared from the print dialog” | B12: Baseline - Configure Windows protected print | C12: Expected | D12: HIGH | E12: Disables ALL third-party v3/v4 print drivers. Only Mopria-certified IPP printers work. Large-format plotters (DesignJet, imagePROGRAF, Océ) and MFP finishing — stapling, booklet, secure/PIN release — stop working. Legacy port monitors and DLL-based print utilities stop working. | F12: Escalate as a scoping decision. There is no client-side fix.
A13: “Nothing happens when I try to install something — it just says access denied” | B13: CISv4 - WIN - L1 - UAC: Behavior of the elevation prompt for standard users | C13: Expected | D13: HIGH | E13: Standard users get NO elevation prompt — the operation returns 'Access denied' and fails. A user cannot be talked through entering admin credentials because no prompt appears. Any install, driver update or self-elevating app just fails. | F13: Do not try to talk the user through a prompt — there isn't one. Use LAPS / admin-by-request / RMM elevation.
A14: “My VM won't start / VMware says it can't run” | B14: CISv4 - WIN - L1 - Credential Guard | C14: Escalate immediately | D14: HIGH | E14: Credential Guard with UEFI lock CANNOT be turned off remotely. If it breaks a developer's VM (VMware without nested virtualisation) or fails on incompatible hardware, the fix needs physical firmware access — a site visit per affected device across 200 endpoints. | F14: Escalate — needs a physical firmware change. Flag early: every affected machine is a site visit.
A15: “I can't save to my USB stick” | B15: Baseline - Device Control | C15: Expected | D15: HIGH | E15: Writing to USB storage is denied — blocks 'copy the drawing set to a stick for site or the client'. DMA blocking can affect Thunderbolt docks and eGPU enclosures used on CAD workstations. | F15: Point the user to the agreed alternative (OneDrive/SharePoint). Do not disable per-device.
... A33: “I can't open an InPrivate window / cast to the meeting room screen” | B33: Edge minor UX set: InPrivate off · Google Cast off · background apps off · profile creation off | C33: Expected | D33: LOW | E33: No InPrivate windows (devs use these to test as an anonymous user), no Google Cast to meeting-room screens, no second browser profile for a personal or client-tenant login. | F33: Expected. Escalate only if meeting rooms depend on Cast.

Sheet Policy Mapping
A1: Policy file | B1: Category | C1: Name in Intune | D1: Graph object shape | E1: WB row | F1: Workbook policy name | G1: Platform | H1: CIS level | I1: Source | J1: Control domain | K1: NIST SP 800-53 Rev 5 | L1: ISO/IEC 27001:2022 | M1: Auditor rationale | N1: Mapping status | O1: Match method | P1: Match note
A2: ASR - BLOCK - Block Office applications from creating executable content | B2: 01_Defender_for_Endpoint (Windows + Linux) | C2: ASR - BLOCK - Block Office applications from creating executable content | D2: settings_catalog_policy | E2: 65 | F2: ASR - BLOCK - Block Office applications from creating executable content | G2: Windows 11 | H2: L1 | I2: Endpoint Security | J2: Attack Surface Reduction (ASR) | K2: SI-3 | L2: 8.7 | M2: Prevents Office from dropping executables to disk — closes macro dropper attack path | N2: mapped | O2: exact
A3: ASR - BLOCK - Block abuse of exploited vulnerable signed drivers (Device) | B3: 01_Defender_for_Endpoint (Windows + Linux) | C3: ASR - BLOCK - Block abuse of exploited vulnerable signed drivers (Device) | D3: settings_catalog_policy | E3: 68 | F3: ASR - BLOCK - Block abuse of exploited vulnerable signed drivers (Device) | G3: Windows 11 | H3: L1 | I3: Endpoint Security | J3: Attack Surface Reduction (ASR) | K3: SI-3 | L3: 8.7 | M3: Blocks BYOVD attacks — prevents exploitation of legitimately signed but vulnerable drivers | N3: mapped | O3: exact
A4: ASR - BLOCK - Block rebooting machine in Safe Mode | B4: 01_Defender_for_Endpoint (Windows + Linux) | C4: ASR - BLOCK - Block rebooting machine in Safe Mode | D4: settings_catalog_policy | E4: 70 | F4: ASR - BLOCK - Block rebooting machine in Safe Mode | G4: Windows 11 | H4: L2 | I4: Endpoint Security | J4: Attack Surface Reduction (ASR) | K4: SI-3 | L4: 8.7 | M4: Prevents malware from rebooting into Safe Mode to evade Defender — closes a common AV bypass technique | N4: mapped | O4: exact
A5: ASR - BLOCK - Enable Controlled Folder Access | B5: 01_Defender_for_Endpoint (Windows + Linux) | C5: ASR - BLOCK - Enable Controlled Folder Access | D5: settings_catalog_policy | E5: 71 | F5: ASR - BLOCK - Enable Controlled Folder Access | G5: Windows 11 | H5: L2 | I5: Endpoint Security | J5: Attack Surface Reduction (ASR) | K5: SI-3 | L5: 8.7 | M5: Set to Audit mode — monitors ransomware-style folder access without blocking. Provides detection evidence for SI-3 without risking false-positive blocks on legitimate apps | N5: mapped | O5: exact
A6: ASR - BLOCK - Use advanced protection against ransomware | B6: 01_Defender_for_Endpoint (Windows + Linux) | C6: ASR - BLOCK - Use advanced protection against ransomware | D6: settings_catalog_policy | E6: 59 | F6: ASR - BLOCK - Use advanced protection against ransomware | G6: Windows 11 | H6: L1 | I6: Endpoint Security | J6: Attack Surface Reduction (ASR) | K6: SI-3 | L6: 8.7 | M6: Ransomware protection specifically called out in ISO 8.7 and SI-3 guidance | N6: mapped | O6: exact
A7: Baseline - App and Browser Isolation | B7: 01_Defender_for_Endpoint (Windows + Linux) | C7: Baseline - App and Browser Isolation | D7: settings_catalog_policy | E7: 96 | F7: Baseline - App and Browser Isolation | G7: Windows 11 | H7: L1 | I7: Endpoint Security | J7: Malware Protection | K7: SI-7, SC-3 | L7: 8.7 | M7: Windows Defender Application Guard / exploit-protection settings - complements the existing ASR rule set. | N7: mapped | O7: exact
A8: Baseline - Chrome Microsoft Defender Browser Protection | B8: 01_Defender_for_Endpoint (Windows + Linux) | C8: Baseline - Chrome Microsoft Defender Browser Protection | D8: settings_catalog_policy | E8: 93 | F8: Baseline - Chrome Microsoft Defender Browser Protection | G8: Chrome | H8: L1 | I8: Endpoint Security | J8: Malware Protection | K8: SI-3, SC-8 | L8: 8.7 | M8: Extends Defender SmartScreen-equivalent protection into Chrome - closes the browser-protection gap on the non-Edge browser. | N8: mapped | O8: exact
A9: Baseline - Defender for Endpoint Linux | B9: 01_Defender_for_Endpoint (Windows + Linux) | C9: Baseline - Defender for Endpoint Linux | D9: settings_catalog_policy | E9: 88 | F9: Baseline - Defender for Endpoint Linux | G9: Linux | H9: L1 | I9: MDE | J9: Linux Endpoint Security | K9: SI-3, SI-2 | L9: 8.7, 8.8 | M9: The only enforceable Linux hardening lever native to Intune - configures AV/EDR behaviour on Linux endpoints via mdatp_managed.json. | N9: mapped | O9: whitespace
A10: Baseline - MDE Device Tag | B10: 01_Defender_for_Endpoint (Windows + Linux) | C10: Baseline - MDE Device Tag | D10: legacy_device_configuration | N10: UNMAPPED — no workbook row | O10: unmapped
A11: Baseline - Microsoft Defender Antivirus | B11: 01_Defender_for_Endpoint (Windows + Linux) | C11: Baseline - Microsoft Defender Antivirus | D11: settings_catalog_policy | E11: 18 | F11: Baseline - Microsoft Defender Antivirus | G11: Windows 11 | H11: L1 | I11: MDE | J11: Malware Protection | K11: SI-3, SI-2, SI-7 | L11: 8.7, 8.8 | M11: 33-setting comprehensive AV policy — covers realtime monitoring, behaviour monitoring, script scanning, network protection, PUA, cloud protection (MAPS), archive scanning, email scanning, scheduled scans, signature updates every 8h, CPU throttling, sample submission, local admin merge prevention. Replaces all individual CIS AV policies. Update channels (engine/platform/sig intelligence) set to Current — Defender always up to date. ⚠ Import via: Devices > Configuration (Settings Catalog) — MDE folder | N11: mapped | O11: exact
A12: Baseline - Microsoft Defender Update controls | B12: 01_Defender_for_Endpoint (Windows + Linux) | C12: Baseline - Defender Update controls | D12: settings_catalog_policy | E12: 90 | F12: Baseline - Microsoft Defender Update controls | G12: Windows 11 | H12: L1 | I12: MDE | J12: Patch Management | K12: SI-2, CM-6 | L12: 8.8 | M12: Governs signature/platform update cadence for Defender itself - closes a patch-management gap specific to the AV engine. | N12: mapped | O12: exact
A13: Baseline - Scareware Blocker in Microsoft Edge | B13: 01_Defender_for_Endpoint (Windows + Linux) | C13: Baseline - Scareware Blocker in Microsoft Edge | D13: settings_catalog_policy | E13: 94 | F13: Baseline - Scareware Blocker in Microsoft Edge | G13: Edge | H13: L1 | I13: Endpoint Security | J13: Malware Protection | K13: SI-3 | L13: 8.7 | M13: Blocks fake tech-support/scareware full-screen pages. Low functional impact, high auditor-visible value. | N13: mapped | O13: exact
A14: Baseline - Smartscreen Enhanced Phishing Protection Block Mode | B14: 01_Defender_for_Endpoint (Windows + Linux) | C14: Baseline - Smartscreen Enhanced Phishing Protection Block Mode | D14: settings_catalog_policy | N14: UNMAPPED — no workbook row | O14: unmapped
A15: Baseline - Windows Defender Security Experience | B15: 01_Defender_for_Endpoint (Windows + Linux) | C15: Baseline - Windows Security Experience | D15: settings_catalog_policy | E15: 19 | F15: Baseline - Windows Defender Security Experience | G15: Windows 11 | H15: L1 | I15: MDE | J15: Malware Protection | K15: SI-3, CM-7 | L15: 8.7, 8.9 | M15: Tamper Protection enabled — prevents users and malware from disabling Defender. Locks Security Center UI panels (family, health, network, notifications). Critical SI-3 control. ⚠ Import via: Devices > Configuration (Settings Catalog) — MDE folder | N15: mapped | O15: exact
A16: CISv3 - EDGE - L1 - Configure Microsoft Defender SmartScreen | B16: 01_Defender_for_Endpoint (Windows + Linux) | C16: CISv3 - EDGE - L1 - Configure Microsoft Defender SmartScreen | D16: settings_catalog_policy | E16: 74 | F16: CISv3 - EDGE - L1 - Configure Microsoft Defender SmartScreen | G16: Edge | H16: L1 | I16: CIS | J16: Edge Browser Security | K16: SI-3 | L16: 8.7, 8.23 | M16: Browser-level SmartScreen is the primary web filtering control — ISO 8.23 evidence | N16: mapped | O16: exact
A17: CISv3 - EDGE - L1 - Prevent bypassing Microsoft Defender SmartScreen prompts for sites | B17: 01_Defender_for_Endpoint (Windows + Linux) | C17: CISv3 - EDGE - L1 - Prevent bypassing Microsoft Defender SmartScreen prompts for sites | D17: settings_catalog_policy | E17: 111 | F17: CISv3 - EDGE - L1 - Prevent bypassing Microsoft Defender SmartScreen prompts for sites | G17: Edge | H17: L1 | I17: CIS | J17: Edge Browser Security | K17: SI-3 | L17: 8.7 | M17: Closes the 'click through the warning' bypass gap on the SmartScreen policy already deployed - pairs directly with an existing control. | N17: mapped | O17: exact
A18: CISv4 - WIN - L1 - ASR Block Adobe Reader from creating child processes | B18: 01_Defender_for_Endpoint (Windows + Linux) | C18: CISv4 - WIN - L1 - ASR: Block Adobe Reader from creating child processes | D18: settings_catalog_policy | E18: 63 | F18: ASR - BLOCK - Block Adobe Reader from creating child processes | G18: Windows 11 | H18: L1 | I18: Endpoint Security | J18: Attack Surface Reduction (ASR) | K18: SI-3 | L18: 8.7 | M18: Prevents PDF-based exploitation — closes a common document-based attack path | N18: mapped | O18: prefix
A19: CISv4 - WIN - L1 - ASR Block JavaScript or VBScript from launching downloaded executable content | B19: 01_Defender_for_Endpoint (Windows + Linux) | C19: CISv4 - WIN - L1 - ASR: Block JavaScript or VBScript from launching downloaded executable content | D19: settings_catalog_policy | E19: 64 | F19: ASR - BLOCK - Block JavaScript or VBScript from launching downloaded executable content | G19: Windows 11 | H19: L1 | I19: Endpoint Security | J19: Attack Surface Reduction (ASR) | K19: SI-3 | L19: 8.7 | M19: Blocks script-based malware delivery — covers a primary web-based attack vector | N19: mapped | O19: prefix
A20: CISv4 - WIN - L1 - ASR Block Office communication application from creating child processes | B20: 01_Defender_for_Endpoint (Windows + Linux) | C20: CISv4 - WIN - L1 - ASR: Block Office communication application from creating child processes | D20: settings_catalog_policy | E20: 66 | F20: ASR - BLOCK - Block Office communication application from creating child processes | G20: Windows 11 | H20: L1 | I20: Endpoint Security | J20: Attack Surface Reduction (ASR) | K20: SI-3 | L20: 8.7 | M20: Blocks Outlook/Teams from spawning child processes — prevents email client exploitation | N20: mapped | O20: prefix
A21: CISv4 - WIN - L1 - ASR Block Win32 API calls from Office macros | B21: 01_Defender_for_Endpoint (Windows + Linux) | C21: CISv4 - WIN - L1 - ASR: Block Win32 API calls from Office macros | D21: settings_catalog_policy | E21: 58 | F21: ASR - BLOCK - Block Win32 API calls from Office macros | G21: Windows 11 | H21: L1 | I21: Endpoint Security | J21: Attack Surface Reduction (ASR) | K21: SI-3 | L21: 8.7 | M21: Macro-based attacks are a top threat vector — directly evidences ISO 8.7 macro controls | N21: mapped | O21: prefix
A22: CISv4 - WIN - L1 - ASR Block all Office applications from creating child processes | B22: 01_Defender_for_Endpoint (Windows + Linux) | C22: CISv4 - WIN - L1 - ASR: Block all Office applications from creating child processes | D22: settings_catalog_policy | E22: 67 | F22: ASR - BLOCK - Block all Office applications from creating child processes | G22: Windows 11 | H22: L1 | I22: Endpoint Security | J22: Attack Surface Reduction (ASR) | K22: SI-3 | L22: 8.7 | M22: Blanket block on Office spawning any child process — strongest Office attack surface control | N22: mapped | O22: prefix
A23: CISv4 - WIN - L1 - ASR Block credential stealing from the Windows local security authority subsystem | B23: 01_Defender_for_Endpoint (Windows + Linux) | C23: CISv4 - WIN - L1 - ASR: Block credential stealing from the Windows local security authority subsystem | D23: settings_catalog_policy | E23: 56 | F23: ASR - BLOCK - Block credential stealing from the Windows local security authority subsystem | G23: Windows 11 | H23: L1 | I23: Endpoint Security | J23: Attack Surface Reduction (ASR) | K23: SI-3, SI-16 | L23: 8.7 | M23: Blocks LSASS dumping — highest-value ASR rule. ES BLOCK policy used: proper template reference, enforced block mode | N23: mapped | O23: prefix
A24: CISv4 - WIN - L1 - ASR Block executable content from email client and webmail | B24: 01_Defender_for_Endpoint (Windows + Linux) | C24: CISv4 - WIN - L1 - ASR: Block executable content from email client and webmail | D24: settings_catalog_policy | E24: 57 | F24: ASR - BLOCK - Block executable content from email client and webmail | G24: Windows 11 | H24: L1 | I24: Endpoint Security | J24: Attack Surface Reduction (ASR) | K24: SI-3 | L24: 8.7 | M24: Email is the primary malware delivery vector — enforced block mode with template reference | N24: mapped | O24: prefix
A25: CISv4 - WIN - L1 - ASR Block executable files from running unless they meet a prevalence, age, or trusted list criterion' | B25: 01_Defender_for_Endpoint (Windows + Linux) | C25: CISv4 - WIN - L1 - ASR: Block executable files from running unless they meet a prevalence, age, or trusted list criterion' | D25: settings_catalog_policy | N25: UNMAPPED — no workbook row | O25: unmapped
A26: CISv4 - WIN - L1 - ASR Block execution of potentially obfuscated scripts | B26: 01_Defender_for_Endpoint (Windows + Linux) | C26: CISv4 - WIN - L1 - ASR: Block execution of potentially obfuscated scripts | D26: settings_catalog_policy | N26: UNMAPPED — no workbook row | O26: unmapped
A27: CISv4 - WIN - L1 - ASR Block persistence through WMI event subscription | B27: 01_Defender_for_Endpoint (Windows + Linux) | C27: CISv4 - WIN - L1 - ASR: Block persistence through WMI event subscription | D27: settings_catalog_policy | E27: 69 | F27: ASR - BLOCK - Block persistence through WMI event subscription | G27: Windows 11 | H27: L1 | I27: Endpoint Security | J27: Attack Surface Reduction (ASR) | K27: SI-3 | L27: 8.7 | M27: Blocks WMI-based persistence — a favourite technique for fileless malware and APT actors | N27: mapped | O27: prefix
A28: CISv4 - WIN - L1 - ASR Block process creations originating from PSExec and WMI commands | B28: 01_Defender_for_Endpoint (Windows + Linux) | C28: CISv4 - WIN - L1 - ASR: Block process creations originating from PSExec and WMI commands | D28: settings_catalog_policy | E28: 61 | F28: CISv4 - WIN - L1 - ASR Block process creations originating from PSExec and WMI commands | G28: Windows 11 | H28: L1 | I28: CIS | J28: Attack Surface Reduction (ASR) | K28: SI-3 | L28: 8.7 | M28: Blocks living-off-the-land lateral movement via PSExec and WMI — CIS L1 version used (no ES BLOCK equivalent exists for this specific rule) | N28: mapped | O28: exact
A29: CISv4 - WIN - L1 - ASR Block untrusted and unsigned processes that run from USB | B29: 01_Defender_for_Endpoint (Windows + Linux) | C29: CISv4 - WIN - L1 - ASR: Block untrusted and unsigned processes that run from USB | D29: settings_catalog_policy | E29: 62 | F29: ASR - BLOCK - Block untrusted and unsigned processes that run from USB | G29: Windows 11 | H29: L1 | I29: Endpoint Security | J29: Attack Surface Reduction (ASR) | K29: SI-3, MP-7 | L29: 8.7 | M29: Blocks malware execution from USB drives — ES BLOCK version with template reference | N29: mapped | O29: prefix
A30: CISv4 - WIN - L2 - Enable File Hash Computation | B30: 01_Defender_for_Endpoint (Windows + Linux) | C30: CISv4 - WIN - L2 - Enable File Hash Computation | D30: settings_catalog_policy | E30: 20 | F30: CISv4 - WIN - L2 - Enable File Hash Computation | G30: Windows 11 | H30: L2 | I30: CIS | J30: Malware Protection | K30: SI-3, SI-7 | L30: 8.7 | M30: Defender computes file hashes for threat intelligence — invisible to users, strengthens SI-3 and SI-7 evidence | N30: mapped | O30: exact
A31: Baseline - Device Password Policy (Consolidated) | B31: 02_Windows_CIS_Benchmark_Hardening | C31: Baseline - Device Password Policy (Consolidated) | D31: settings_catalog_policy | E31: 1 | F31: Baseline - Device Password Policy (Consolidated) | G31: Windows 11 | H31: L1 | I31: CIS | J31: Authentication & Account Security | K31: IA-5, AC-11, AC-7 | L31: 8.5, 8.1, 5.17 | M31: Consolidates the 6 separate 'Device Password Enabled...' policies from the original baseline into one. The DeviceLock CSP requires all child settings (min length, complexity, lockout, inactivity, history) to travel together under one parent setting — deploying the original 6 as separate policies to the same device causes a genuine Intune Settings Catalog conflict, since each file reset the others' settings back to schema defaults. Fixed 2026-09: min length 14, alphanumeric required, 5 failed attempts, 15 min inactivity, 24-password history, enabled. | N31: mapped | O31: exact
A32: CISv4 - WIN - L1 - 'User Account Control Behavior of the elevation prompt for standard users | B32: 02_Windows_CIS_Benchmark_Hardening | C32: CISv4 - WIN - L1 - 'User Account Control: Behavior of the elevation prompt for standard users | D32: settings_catalog_policy | E32: 31 | F32: CISv4 - WIN - L1 - 'User Account Control Behavior of the elevation prompt for standard users | G32: Windows 11 | H32: L1 | I32: CIS | J32: UAC & Privileged Access | K32: AC-6 | L32: 8.2 | M32: Ensures standard users cannot self-elevate — AC-6 least privilege enforcement | N32: mapped | O32: exact
A33: CISv4 - WIN - L1 - Accounts Enable Guest account status | B33: 02_Windows_CIS_Benchmark_Hardening | C33: CISv4 - WIN - L1 - Accounts: Enable Guest account status | D33: settings_catalog_policy | E33: 2 | F33: CISv4 - WIN - L1 - Accounts Enable Guest account status | G33: Windows 11 | H33: L1 | I33: CIS | J33: Authentication & Account Security | K33: AC-2 | L33: 5.16, 8.2 | M33: Disabling guest access is a mandatory AC-2 control — auditors always check this | N33: mapped | O33: exact
A34: CISv4 - WIN - L1 - Accounts Limit local account use of blank passwords to console logon only' | B34: 02_Windows_CIS_Benchmark_Hardening | C34: CISv4 - WIN - L1 - Accounts: Limit local account use of blank passwords to console logon only' | D34: settings_catalog_policy | E34: 3 | F34: CISv4 - WIN - L1 - Accounts Limit local account use of blank passwords to console logon only' | G34: Windows 11 | H34: L1 | I34: CIS | J34: Authentication & Account Security | K34: IA-5 | L34: 8.5, 5.17 | M34: Blocks remote access with blank passwords — critical IA-5 evidence | N34: mapped | O34: exact
A35: CISv4 - WIN - L1 - Accounts Rename administrator account | B35: 02_Windows_CIS_Benchmark_Hardening | C35: CISv4 - WIN - L1 - Accounts: Rename administrator account | D35: settings_catalog_policy | E35: 4 | F35: CISv4 - WIN - L1 - Accounts Rename administrator account | G35: Windows 11 | H35: L1 | I35: CIS | J35: Authentication & Account Security | K35: AC-2, AC-6 | L35: 5.16, 8.2 | M35: Removes predictable attack target — standard auditor check for AC-2/AC-6 | N35: mapped | O35: exact
A36: CISv4 - WIN - L1 - Allow Basic authentication WinRM Client | B36: 02_Windows_CIS_Benchmark_Hardening | C36: CISv4 - WIN - L1 - Allow Basic authentication WinRM Client | D36: settings_catalog_policy | N36: UNMAPPED — no workbook row | O36: unmapped
A37: CISv4 - WIN - L1 - Allow Indexing Encrypted Stores Or Items | B37: 02_Windows_CIS_Benchmark_Hardening | C37: CISv4 - WIN - L1 - Allow Indexing Encrypted Stores Or Items | D37: settings_catalog_policy | N37: UNMAPPED — no workbook row | O37: unmapped
A38: CISv4 - WIN - L1 - Always prompt for password upon connection | B38: 02_Windows_CIS_Benchmark_Hardening | C38: CISv4 - WIN - L1 - Always prompt for password upon connection | D38: settings_catalog_policy | E38: 41 | F38: CISv4 - WIN - L1 - Always prompt for password upon connection | G38: Windows 11 | H38: L1 | I38: CIS | J38: Remote Access | K38: AC-17, IA-2 | L38: 8.5 | M38: Prevents credential caching on RDP reconnect — AC-17 and ISO 8.5 evidence | N38: mapped | O38: exact
A39: CISv4 - WIN - L1 - Apply UAC restrictions to local accounts on network logons | B39: 02_Windows_CIS_Benchmark_Hardening | C39: CISv4 - WIN - L1 - Apply UAC restrictions to local accounts on network logons | D39: settings_catalog_policy | E39: 32 | F39: CISv4 - WIN - L1 - Apply UAC restrictions to local accounts on network logons | G39: Windows 11 | H39: L1 | I39: CIS | J39: UAC & Privileged Access | K39: AC-6, AC-3 | L39: 8.2 | M39: Prevents pass-the-hash lateral movement via local admin — critical AC-6 network control | N39: mapped | O39: exact
A40: CISv4 - WIN - L1 - Configure Lsa Protected Process is set to 'Enabled with UEFI Lock | B40: 02_Windows_CIS_Benchmark_Hardening | C40: CISv4 - WIN - L1 - Configure Lsa Protected Process is set to 'Enabled with UEFI Lock... | D40: settings_catalog_policy | E40: 27 | F40: CISv4 - WIN - L1 - Configure Lsa Protected Process is set to 'Enabled with UEFI Lock | G40: Windows 11 | H40: L1 | I40: CIS | J40: Credential Protection | K40: SC-3, SI-16 | L40: 8.1 | M40: LSA protection prevents credential dumping — key evidence for SI-16 and ISO 8.1 | N40: mapped | O40: exact
...

Sheet Control Coverage
A1: Framework | B1: Control | C1: Policies mapped | D1: Control domains covered
A2: ISO/IEC 27001:2022 | B2: 8.7 | C2: =COUNTIFS('Policy x Control'!A:A,A2,'Policy x Control'!B:B,B2) -> 65 | D2: Attack Surface Reduction (ASR), Browser Security (Chrome), Edge Browser Security, Linux Endpoint Security, Malware Protection, Privacy & Data Governance, Removable Media & USB
A3: ISO/IEC 27001:2022 | B3: 8.9 | C3: =COUNTIFS('Policy x Control'!A:A,A3,'Policy x Control'!B:B,B3) -> 39 | D3: AI & Data Governance, Attack Surface Reduction (ASR), Browser Security (Chrome), Edge Browser Security, Identity & Account Control, Linux Endpoint Security, Malware Protection, Network Security, Privacy & Data Governance, Removable Media & USB, UAC & Privileged Access
A4: ISO/IEC 27001:2022 | B4: 8.5 | C4: =COUNTIFS('Policy x Control'!A:A,A4,'Policy x Control'!B:B,B4) -> 23 | D4: Authentication & Account Security, Browser Security (Chrome), Credential Protection, Edge Browser Security, Identity & Account Control, Network Security, Passwordless Authentication, Remote Access
A5: ISO/IEC 27001:2022 | B5: 8.20 | C5: =COUNTIFS('Policy x Control'!A:A,A5,'Policy x Control'!B:B,B5) -> 21 | D5: Edge Browser Security, Firewall, Network Security, Privacy & Data Governance, Remote Access
A6: ISO/IEC 27001:2022 | B6: 8.8 | C6: =COUNTIFS('Policy x Control'!A:A,A6,'Policy x Control'!B:B,B6) -> 17 | D6: Linux Endpoint Security, Malware Protection, Patch Management
A7: ISO/IEC 27001:2022 | B7: 8.15 | C7: =COUNTIFS('Policy x Control'!A:A,A7,'Policy x Control'!B:B,B7) -> 10 | D7: Audit & Logging
A8: ISO/IEC 27001:2022 | B8: 8.1 | C8: =COUNTIFS('Policy x Control'!A:A,A8,'Policy x Control'!B:B,B8) -> 8 | D8: Authentication & Account Security, Credential Protection, Identity & Account Control, Remote Access, Screen Lock & Session
A9: ISO/IEC 27001:2022 | B9: 8.2 | C9: =COUNTIFS('Policy x Control'!A:A,A9,'Policy x Control'!B:B,B9) -> 8 | D9: Authentication & Account Security, UAC & Privileged Access
A10: ISO/IEC 27001:2022 | B10: 8.24 | C10: =COUNTIFS('Policy x Control'!A:A,A10,'Policy x Control'!B:B,B10) -> 7 | D10: Edge Browser Security, Encryption at Rest, Network Security, Privacy & Data Governance
A11: ISO/IEC 27001:2022 | B11: 5.16 | C11: =COUNTIFS('Policy x Control'!A:A,A11,'Policy x Control'!B:B,B11) -> 5 | D11: Authentication & Account Security, Identity & Account Control
A12: ISO/IEC 27001:2022 | B12: 5.17 | C12: =COUNTIFS('Policy x Control'!A:A,A12,'Policy x Control'!B:B,B12) -> 4 | D12: Authentication & Account Security, Credential Protection
A13: ISO/IEC 27001:2022 | B13: 8.13 | C13: =COUNTIFS('Policy x Control'!A:A,A13,'Policy x Control'!B:B,B13) -> 2 | D13: Resilience & Recovery
... A48: NIST SP 800-53 Rev 5 | B48: SC-13 | C48: =COUNTIFS('Policy x Control'!A:A,A48,'Policy x Control'!B:B,B48) -> 1 | D48: Network Security

Sheet Policy x Control
A1: Framework | B1: Control | C1: Policy file | D1: Category | E1: Control domain | F1: CIS level | G1: Platform | H1: Mapping status
A2: ISO/IEC 27001:2022 | B2: (no workbook row) | C2: Baseline - Device Control | D2: 08_Removable_Media_and_Device_Control | H2: UNMAPPED — no workbook row
